from django.core.exceptions import ValidationError
from rest_framework import fields, serializers
from apps.users.models import User


class UserSerializer(serializers.ModelSerializer):
    class Meta:
        model = User
        fields = '__all__'

    def create(self, validated_data):
        user = User(**validated_data)
        user.set_password(validated_data['password'])
        user.save()
        return user

    def update(self, instance, validated_data):
        update_user = super().update(instance, validated_data)
        update_user.set_password(validated_data['password'])
        update_user.save()
        return update_user


class UserListSerializer(serializers.ModelSerializer):

    class Meta:
        model = User

    def to_representation(self, instance):
        return {
            'id': instance['id'],
            'name': instance['name'],
            'username': instance['username'],
            'email': instance['email'],
            'password': instance['password'],
        }
